Workbook

Sheet Resum
A2: Inventari general - GRAE Muntanya
A4: PERSONES ACTIVES | B4: ARTICLES CATÀLEG | C4: UNITATS TEÒRIQUES | D4: UNITATS DECLARADES | E4: UNITATS PENDENTS | F4: A SUBSTITUIR | G4: NO LOCALITZAT | H4: REGISTRES PENDENTS | L4: Base / grup | M4: Caporals | N4: Bombers
A5: =COUNTIF(Personal!$E$6:$E$112,"Sí") -> 107 | B5: =COUNTA('Catàleg GRAE'!$C$5:$C$113) -> 109 | C5: =SUM(Declaracions!$H$6:$H$11668) -> 14338 | D5: =SUM(Declaracions!$I$6:$I$11668) -> 0 | E5: =SUMIF(Declaracions!$P$6:$P$11668,"<0",Declaracions!$P$6:$P$11668)*-1 -> 0 | F5: =COUNTIF(Declaracions!$N$6:$N$11668,"Per substituir") -> 0 | G5: =COUNTIF(Declaracions!$N$6:$N$11668,"No localitzat") -> 0 | H5: =COUNTIF(Declaracions!$H$6:$H$11668,">0")-COUNT(Declaracions!$I$6:$I$11668) -> 11663 | L5: Olot | M5: =COUNTIFS(Personal!$C$6:$C$112,L5,Personal!$D$6:$D$112,"Caporal GRAE Muntanya") -> 6 | N5: =COUNTIFS(Personal!$C$6:$C$112,L5,Personal!$D$6:$D$112,"Bomber/a especialista GRAE Muntanya") -> 18
L6: La Seu d’Urgell | M6: =COUNTIFS(Personal!$C$6:$C$112,L6,Personal!$D$6:$D$112,"Caporal GRAE Muntanya") -> 6 | N6: =COUNTIFS(Personal!$C$6:$C$112,L6,Personal!$D$6:$D$112,"Bomber/a especialista GRAE Muntanya") -> 18
L7: Valls | M7: =COUNTIFS(Personal!$C$6:$C$112,L7,Personal!$D$6:$D$112,"Caporal GRAE Muntanya") -> 6 | N7: =COUNTIFS(Personal!$C$6:$C$112,L7,Personal!$D$6:$D$112,"Bomber/a especialista GRAE Muntanya") -> 18
A8: Categoria | B8: Referència | C8: Article | D8: Dotació/persona | E8: Teòric total | F8: Declarat | G8: Manca | H8: Per substituir | I8: No localitzat | J8: Situació | L8: Cerdanyola | M8: =COUNTIFS(Personal!$C$6:$C$112,L8,Personal!$D$6:$D$112,"Caporal GRAE Muntanya") -> 6 | N8: =COUNTIFS(Personal!$C$6:$C$112,L8,Personal!$D$6:$D$112,"Bomber/a especialista GRAE Muntanya") -> 18
A9: Uniformitat | B9: COS-PO-02 | C9: Polo màniga curta blau marí (bomber/a) | D9: 1 | E9: =SUMIF(Declaracions!$F$6:$F$11668,C9,Declaracions!$H$6:$H$11668) -> 107 | F9: =SUMIF(Declaracions!$F$6:$F$11668,C9,Declaracions!$I$6:$I$11668) -> 0 | G9: =MAX(0,E9-F9) -> 107 | H9: =COUNTIFS(Declaracions!$F$6:$F$11668,C9,Declaracions!$N$6:$N$11668,"Per substituir") -> 0 | I9: =COUNTIFS(Declaracions!$F$6:$F$11668,C9,Declaracions!$N$6:$N$11668,"No localitzat") -> 0 | J9: =IF(G9>0,"Reposar",IF(OR(H9>0,I9>0),"Revisar","OK")) -> Reposar | L9: Comandaments responsables | M9: =COUNTIF(Personal!$D$6:$D$112,"Comandament responsable") -> 11
A10: Uniformitat | B10: COS-PO-02 | C10: Polo màniga llarga blau marí (bomber/a) | D10: 1 | E10: =SUMIF(Declaracions!$F$6:$F$11668,C10,Declaracions!$H$6:$H$11668) -> 107 | F10: =SUMIF(Declaracions!$F$6:$F$11668,C10,Declaracions!$I$6:$I$11668) -> 0 | G10: =MAX(0,E10-F10) -> 107 | H10: =COUNTIFS(Declaracions!$F$6:$F$11668,C10,Declaracions!$N$6:$N$11668,"Per substituir") -> 0 | I10: =COUNTIFS(Declaracions!$F$6:$F$11668,C10,Declaracions!$N$6:$N$11668,"No localitzat") -> 0 | J10: =IF(G10>0,"Reposar",IF(OR(H10>0,I10>0),"Revisar","OK")) -> Reposar
A11: Uniformitat | B11: COS-PA-08 | C11: Pantaló d’intervenció lleuger | D11: 1 | E11: =SUMIF(Declaracions!$F$6:$F$11668,C11,Declaracions!$H$6:$H$11668) -> 107 | F11: =SUMIF(Declaracions!$F$6:$F$11668,C11,Declaracions!$I$6:$I$11668) -> 0 | G11: =MAX(0,E11-F11) -> 107 | H11: =COUNTIFS(Declaracions!$F$6:$F$11668,C11,Declaracions!$N$6:$N$11668,"Per substituir") -> 0 | I11: =COUNTIFS(Declaracions!$F$6:$F$11668,C11,Declaracions!$N$6:$N$11668,"No localitzat") -> 0 | J11: =IF(G11>0,"Reposar",IF(OR(H11>0,I11>0),"Revisar","OK")) -> Reposar
A12: Uniformitat | B12: COS-SA-01 | C12: Samarreta | D12: 2 | E12: =SUMIF(Declaracions!$F$6:$F$11668,C12,Declaracions!$H$6:$H$11668) -> 214 | F12: =SUMIF(Declaracions!$F$6:$F$11668,C12,Declaracions!$I$6:$I$11668) -> 0 | G12: =MAX(0,E12-F12) -> 214 | H12: =COUNTIFS(Declaracions!$F$6:$F$11668,C12,Declaracions!$N$6:$N$11668,"Per substituir") -> 0 | I12: =COUNTIFS(Declaracions!$F$6:$F$11668,C12,Declaracions!$N$6:$N$11668,"No localitzat") -> 0 | J12: =IF(G12>0,"Reposar",IF(OR(H12>0,I12>0),"Revisar","OK")) -> Reposar
A13: Uniformitat | B13: COS-CI-01 | C13: Cinturó de treball | D13: 1 | E13: =SUMIF(Declaracions!$F$6:$F$11668,C13,Declaracions!$H$6:$H$11668) -> 107 | F13: =SUMIF(Declaracions!$F$6:$F$11668,C13,Declaracions!$I$6:$I$11668) -> 0 | G13: =MAX(0,E13-F13) -> 107 | H13: =COUNTIFS(Declaracions!$F$6:$F$11668,C13,Declaracions!$N$6:$N$11668,"Per substituir") -> 0 | I13: =COUNTIFS(Declaracions!$F$6:$F$11668,C13,Declaracions!$N$6:$N$11668,"No localitzat") -> 0 | J13: =IF(G13>0,"Reposar",IF(OR(H13>0,I13>0),"Revisar","OK")) -> Reposar
A14: Transport | B14: MAT-BO-01 / MAT-BO-07 | C14: Bossa de transport amb motxilla | D14: 1 | E14: =SUMIF(Declaracions!$F$6:$F$11668,C14,Declaracions!$H$6:$H$11668) -> 107 | F14: =SUMIF(Declaracions!$F$6:$F$11668,C14,Declaracions!$I$6:$I$11668) -> 0 | G14: =MAX(0,E14-F14) -> 107 | H14: =COUNTIFS(Declaracions!$F$6:$F$11668,C14,Declaracions!$N$6:$N$11668,"Per substituir") -> 0 | I14: =COUNTIFS(Declaracions!$F$6:$F$11668,C14,Declaracions!$N$6:$N$11668,"No localitzat") -> 0 | J14: =IF(G14>0,"Reposar",IF(OR(H14>0,I14>0),"Revisar","OK")) -> Reposar
A15: Protecció | B15: MAN-FO-01 | C15: Guants de protecció en incendis forestals | D15: 1 | E15: =SUMIF(Declaracions!$F$6:$F$11668,C15,Declaracions!$H$6:$H$11668) -> 107 | F15: =SUMIF(Declaracions!$F$6:$F$11668,C15,Declaracions!$I$6:$I$11668) -> 0 | G15: =MAX(0,E15-F15) -> 107 | H15: =COUNTIFS(Declaracions!$F$6:$F$11668,C15,Declaracions!$N$6:$N$11668,"Per substituir") -> 0 | I15: =COUNTIFS(Declaracions!$F$6:$F$11668,C15,Declaracions!$N$6:$N$11668,"No localitzat") -> 0 | J15: =IF(G15>0,"Reposar",IF(OR(H15>0,I15>0),"Revisar","OK")) -> Reposar
A16: Protecció | B16: CAP-MA-04 | C16: Mascareta autofiltrant FFP3 | D16: 1 | E16: =SUMIF(Declaracions!$F$6:$F$11668,C16,Declaracions!$H$6:$H$11668) -> 107 | F16: =SUMIF(Declaracions!$F$6:$F$11668,C16,Declaracions!$I$6:$I$11668) -> 0 | G16: =MAX(0,E16-F16) -> 107 | H16: =COUNTIFS(Declaracions!$F$6:$F$11668,C16,Declaracions!$N$6:$N$11668,"Per substituir") -> 0 | I16: =COUNTIFS(Declaracions!$F$6:$F$11668,C16,Declaracions!$N$6:$N$11668,"No localitzat") -> 0 | J16: =IF(G16>0,"Reposar",IF(OR(H16>0,I16>0),"Revisar","OK")) -> Reposar
A17: Esport | B17: COS-DE-02 | C17: Dessuadora d’esport | D17: 1 | E17: =SUMIF(Declaracions!$F$6:$F$11668,C17,Declaracions!$H$6:$H$11668) -> 107 | F17: =SUMIF(Declaracions!$F$6:$F$11668,C17,Declaracions!$I$6:$I$11668) -> 0 | G17: =MAX(0,E17-F17) -> 107 | H17: =COUNTIFS(Declaracions!$F$6:$F$11668,C17,Declaracions!$N$6:$N$11668,"Per substituir") -> 0 | I17: =COUNTIFS(Declaracions!$F$6:$F$11668,C17,Declaracions!$N$6:$N$11668,"No localitzat") -> 0 | J17: =IF(G17>0,"Reposar",IF(OR(H17>0,I17>0),"Revisar","OK")) -> Reposar
A18: Esport | B18: COS-PA-10 | C18: Pantaló llarg d’esport | D18: 1 | E18: =SUMIF(Declaracions!$F$6:$F$11668,C18,Declaracions!$H$6:$H$11668) -> 107 | F18: =SUMIF(Declaracions!$F$6:$F$11668,C18,Declaracions!$I$6:$I$11668) -> 0 | G18: =MAX(0,E18-F18) -> 107 | H18: =COUNTIFS(Declaracions!$F$6:$F$11668,C18,Declaracions!$N$6:$N$11668,"Per substituir") -> 0 | I18: =COUNTIFS(Declaracions!$F$6:$F$11668,C18,Declaracions!$N$6:$N$11668,"No localitzat") -> 0 | J18: =IF(G18>0,"Reposar",IF(OR(H18>0,I18>0),"Revisar","OK")) -> Reposar
A19: Esport | B19: COS-PA-07 | C19: Pantaló curt d’esport | D19: 1 | E19: =SUMIF(Declaracions!$F$6:$F$11668,C19,Declaracions!$H$6:$H$11668) -> 107 | F19: =SUMIF(Declaracions!$F$6:$F$11668,C19,Declaracions!$I$6:$I$11668) -> 0 | G19: =MAX(0,E19-F19) -> 107 | H19: =COUNTIFS(Declaracions!$F$6:$F$11668,C19,Declaracions!$N$6:$N$11668,"Per substituir") -> 0 | I19: =COUNTIFS(Declaracions!$F$6:$F$11668,C19,Declaracions!$N$6:$N$11668,"No localitzat") -> 0 | J19: =IF(G19>0,"Reposar",IF(OR(H19>0,I19>0),"Revisar","OK")) -> Reposar
A20: Esport | B20: COS-SA-02 | C20: Samarreta d’esport | D20: 1 | E20: =SUMIF(Declaracions!$F$6:$F$11668,C20,Declaracions!$H$6:$H$11668) -> 107 | F20: =SUMIF(Declaracions!$F$6:$F$11668,C20,Declaracions!$I$6:$I$11668) -> 0 | G20: =MAX(0,E20-F20) -> 107 | H20: =COUNTIFS(Declaracions!$F$6:$F$11668,C20,Declaracions!$N$6:$N$11668,"Per substituir") -> 0 | I20: =COUNTIFS(Declaracions!$F$6:$F$11668,C20,Declaracions!$N$6:$N$11668,"No localitzat") -> 0 | J20: =IF(G20>0,"Reposar",IF(OR(H20>0,I20>0),"Revisar","OK")) -> Reposar
A21: Esport | B21: PEU-SA-01 | C21: Calçat d’esport | D21: 1 | E21: =SUMIF(Declaracions!$F$6:$F$11668,C21,Declaracions!$H$6:$H$11668) -> 107 | F21: =SUMIF(Declaracions!$F$6:$F$11668,C21,Declaracions!$I$6:$I$11668) -> 0 | G21: =MAX(0,E21-F21) -> 107 | H21: =COUNTIFS(Declaracions!$F$6:$F$11668,C21,Declaracions!$N$6:$N$11668,"Per substituir") -> 0 | I21: =COUNTIFS(Declaracions!$F$6:$F$11668,C21,Declaracions!$N$6:$N$11668,"No localitzat") -> 0 | J21: =IF(G21>0,"Reposar",IF(OR(H21>0,I21>0),"Revisar","OK")) -> Reposar
... A117: Aquàtic | B117: MAT-CO-42 | C117: Banyador corporatiu GRAE | D117: 1 | E117: =SUMIF(Declaracions!$F$6:$F$11668,C117,Declaracions!$H$6:$H$11668) -> 107 | F117: =SUMIF(Declaracions!$F$6:$F$11668,C117,Declaracions!$I$6:$I$11668) -> 0 | G117: =MAX(0,E117-F117) -> 107 | H117: =COUNTIFS(Declaracions!$F$6:$F$11668,C117,Declaracions!$N$6:$N$11668,"Per substituir") -> 0 | I117: =COUNTIFS(Declaracions!$F$6:$F$11668,C117,Declaracions!$N$6:$N$11668,"No localitzat") -> 0 | J117: =IF(G117>0,"Reposar",IF(OR(H117>0,I117>0),"Revisar","OK")) -> Reposar

Sheet Personal
A2: Personal inclòs en l’inventari
A3: Omple una fila per especialista. El camp Actiu controla si la persona entra en els càlculs.
A5: ID | B5: Nom i cognoms | C5: Base / parc | D5: Categoria | E5: Actiu | F5: Data comprovació
A6: 1 | C6: Olot | D6: Caporal GRAE Muntanya | E6: Sí
A7: 2 | C7: Olot | D7: Caporal GRAE Muntanya | E7: Sí
A8: 3 | C8: Olot | D8: Caporal GRAE Muntanya | E8: Sí
A9: 4 | C9: Olot | D9: Caporal GRAE Muntanya | E9: Sí
A10: 5 | C10: Olot | D10: Caporal GRAE Muntanya | E10: Sí
A11: 6 | C11: Olot | D11: Caporal GRAE Muntanya | E11: Sí
A12: 7 | C12: Olot | D12: Bomber/a especialista GRAE Muntanya | E12: Sí
A13: 8 | C13: Olot | D13: Bomber/a especialista GRAE Muntanya | E13: Sí
A14: 9 | C14: Olot | D14: Bomber/a especialista GRAE Muntanya | E14: Sí
A15: 10 | C15: Olot | D15: Bomber/a especialista GRAE Muntanya | E15: Sí
A16: 11 | C16: Olot | D16: Bomber/a especialista GRAE Muntanya | E16: Sí
A17: 12 | C17: Olot | D17: Bomber/a especialista GRAE Muntanya | E17: Sí
... A101: 96 | C101: Cerdanyola | D101: Bomber/a especialista GRAE Muntanya | E101: Sí
A102: 97 | D102: Comandament responsable | E102: Sí
A103: 98 | D103: Comandament responsable | E103: Sí
A104: 99 | D104: Comandament responsable | E104: Sí
A105: 100 | D105: Comandament responsable | E105: Sí
A106: 101 | D106: Comandament responsable | E106: Sí
A107: 102 | D107: Comandament responsable | E107: Sí
A108: 103 | D108: Comandament responsable | E108: Sí
A109: 104 | D109: Comandament responsable | E109: Sí
A110: 105 | D110: Comandament responsable | E110: Sí
A111: 106 | D111: Comandament responsable | E111: Sí
A112: 107 | D112: Comandament responsable | E112: Sí

Sheet Declaracions
A2: Declaració individual de material i control EPI
A3: Filtra per ID, nom o base. El número de sèrie/lot és opcional. En els EPI, informa les dates disponibles de fabricació, alta, caducitat o revisió.
A5: ID persona | B5: Nom i cognoms | C5: Base / parc | D5: Categoria material | E5: Referència | F5: Article | G5: EPI traçable | H5: Dotació teòrica | I5: Unitats disponibles | J5: Talla / mida | K5: Núm. sèrie / lot EPI | L5: Data fabricació / alta | M5: Caducitat / pròxima revisió | N5: Estat | O5: Observacions | P5: Diferència | Q5: Acció / control EPI | R5: Comprovat
A6: 1 | B6: =IFERROR(VLOOKUP(A6,Personal!$A$6:$F$112,2,FALSE()),"") -> 0 | C6: =IFERROR(VLOOKUP(A6,Personal!$A$6:$F$112,3,FALSE()),"") -> Olot | D6: Uniformitat | E6: COS-PO-02 | F6: Polo màniga curta blau marí (bomber/a) | G6: No | H6: =IF(OR(VLOOKUP(A6,Personal!$A$6:$F$112,5,FALSE())<>"Sí",N6="No aplica"),0,'Catàleg GRAE'!D5) -> 1 | P6: =IF(I6="","",I6-H6) | Q6: =IF(B6="","",IF(N6="No aplica","No aplica",IF(I6="","Pendent",IF(N6="Per substituir","Substituir",IF(OR(N6="No localitzat",N6="No lliurat"),"Reposar",IF(I6<H6,"Reposar",IF(I6>H6,"Revisar excedent",IF(AND(G6="Sí",M6<>"",M6<TODAY()),"EPI caducat",IF(AND(G6="Sí",M6<>"",M6<=TODAY()+90),"EPI caduca ≤90 dies",IF(OR(N6="Deteriorat usable",N6="Revisió necessària"),"Revisar","OK"))))))))))
A7: 1 | B7: =IFERROR(VLOOKUP(A7,Personal!$A$6:$F$112,2,FALSE()),"") -> 0 | C7: =IFERROR(VLOOKUP(A7,Personal!$A$6:$F$112,3,FALSE()),"") -> Olot | D7: Uniformitat | E7: COS-PO-02 | F7: Polo màniga llarga blau marí (bomber/a) | G7: No | H7: =IF(OR(VLOOKUP(A7,Personal!$A$6:$F$112,5,FALSE())<>"Sí",N7="No aplica"),0,'Catàleg GRAE'!D6) -> 1 | P7: =IF(I7="","",I7-H7) | Q7: =IF(B7="","",IF(N7="No aplica","No aplica",IF(I7="","Pendent",IF(N7="Per substituir","Substituir",IF(OR(N7="No localitzat",N7="No lliurat"),"Reposar",IF(I7<H7,"Reposar",IF(I7>H7,"Revisar excedent",IF(AND(G7="Sí",M7<>"",M7<TODAY()),"EPI caducat",IF(AND(G7="Sí",M7<>"",M7<=TODAY()+90),"EPI caduca ≤90 dies",IF(OR(N7="Deteriorat usable",N7="Revisió necessària"),"Revisar","OK"))))))))))
A8: 1 | B8: =IFERROR(VLOOKUP(A8,Personal!$A$6:$F$112,2,FALSE()),"") -> 0 | C8: =IFERROR(VLOOKUP(A8,Personal!$A$6:$F$112,3,FALSE()),"") -> Olot | D8: Uniformitat | E8: COS-PA-08 | F8: Pantaló d’intervenció lleuger | G8: Sí | H8: =IF(OR(VLOOKUP(A8,Personal!$A$6:$F$112,5,FALSE())<>"Sí",N8="No aplica"),0,'Catàleg GRAE'!D7) -> 1 | P8: =IF(I8="","",I8-H8) | Q8: =IF(B8="","",IF(N8="No aplica","No aplica",IF(I8="","Pendent",IF(N8="Per substituir","Substituir",IF(OR(N8="No localitzat",N8="No lliurat"),"Reposar",IF(I8<H8,"Reposar",IF(I8>H8,"Revisar excedent",IF(AND(G8="Sí",M8<>"",M8<TODAY()),"EPI caducat",IF(AND(G8="Sí",M8<>"",M8<=TODAY()+90),"EPI caduca ≤90 dies",IF(OR(N8="Deteriorat usable",N8="Revisió necessària"),"Revisar","OK"))))))))))
A9: 1 | B9: =IFERROR(VLOOKUP(A9,Personal!$A$6:$F$112,2,FALSE()),"") -> 0 | C9: =IFERROR(VLOOKUP(A9,Personal!$A$6:$F$112,3,FALSE()),"") -> Olot | D9: Uniformitat | E9: COS-SA-01 | F9: Samarreta | G9: No | H9: =IF(OR(VLOOKUP(A9,Personal!$A$6:$F$112,5,FALSE())<>"Sí",N9="No aplica"),0,'Catàleg GRAE'!D8) -> 2 | P9: =IF(I9="","",I9-H9) | Q9: =IF(B9="","",IF(N9="No aplica","No aplica",IF(I9="","Pendent",IF(N9="Per substituir","Substituir",IF(OR(N9="No localitzat",N9="No lliurat"),"Reposar",IF(I9<H9,"Reposar",IF(I9>H9,"Revisar excedent",IF(AND(G9="Sí",M9<>"",M9<TODAY()),"EPI caducat",IF(AND(G9="Sí",M9<>"",M9<=TODAY()+90),"EPI caduca ≤90 dies",IF(OR(N9="Deteriorat usable",N9="Revisió necessària"),"Revisar","OK"))))))))))
A10: 1 | B10: =IFERROR(VLOOKUP(A10,Personal!$A$6:$F$112,2,FALSE()),"") -> 0 | C10: =IFERROR(VLOOKUP(A10,Personal!$A$6:$F$112,3,FALSE()),"") -> Olot | D10: Uniformitat | E10: COS-CI-01 | F10: Cinturó de treball | G10: No | H10: =IF(OR(VLOOKUP(A10,Personal!$A$6:$F$112,5,FALSE())<>"Sí",N10="No aplica"),0,'Catàleg GRAE'!D9) -> 1 | P10: =IF(I10="","",I10-H10) | Q10: =IF(B10="","",IF(N10="No aplica","No aplica",IF(I10="","Pendent",IF(N10="Per substituir","Substituir",IF(OR(N10="No localitzat",N10="No lliurat"),"Reposar",IF(I10<H10,"Reposar",IF(I10>H10,"Revisar excedent",IF(AND(G10="Sí",M10<>"",M10<TODAY()),"EPI caducat",IF(AND(G10="Sí",M10<>"",M10<=TODAY()+90),"EPI caduca ≤90 dies",IF(OR(N10="Deteriorat usable",N10="Revisió necessària"),"Revisar","OK"))))))))))
A11: 1 | B11: =IFERROR(VLOOKUP(A11,Personal!$A$6:$F$112,2,FALSE()),"") -> 0 | C11: =IFERROR(VLOOKUP(A11,Personal!$A$6:$F$112,3,FALSE()),"") -> Olot | D11: Transport | E11: MAT-BO-01 / MAT-BO-07 | F11: Bossa de transport amb motxilla | G11: No | H11: =IF(OR(VLOOKUP(A11,Personal!$A$6:$F$112,5,FALSE())<>"Sí",N11="No aplica"),0,'Catàleg GRAE'!D10) -> 1 | P11: =IF(I11="","",I11-H11) | Q11: =IF(B11="","",IF(N11="No aplica","No aplica",IF(I11="","Pendent",IF(N11="Per substituir","Substituir",IF(OR(N11="No localitzat",N11="No lliurat"),"Reposar",IF(I11<H11,"Reposar",IF(I11>H11,"Revisar excedent",IF(AND(G11="Sí",M11<>"",M11<TODAY()),"EPI caducat",IF(AND(G11="Sí",M11<>"",M11<=TODAY()+90),"EPI caduca ≤90 dies",IF(OR(N11="Deteriorat usable",N11="Revisió necessària"),"Revisar","OK"))))))))))
A12: 1 | B12: =IFERROR(VLOOKUP(A12,Personal!$A$6:$F$112,2,FALSE()),"") -> 0 | C12: =IFERROR(VLOOKUP(A12,Personal!$A$6:$F$112,3,FALSE()),"") -> Olot | D12: Protecció | E12: MAN-FO-01 | F12: Guants de protecció en incendis forestals | G12: Sí | H12: =IF(OR(VLOOKUP(A12,Personal!$A$6:$F$112,5,FALSE())<>"Sí",N12="No aplica"),0,'Catàleg GRAE'!D11) -> 1 | P12: =IF(I12="","",I12-H12) | Q12: =IF(B12="","",IF(N12="No aplica","No aplica",IF(I12="","Pendent",IF(N12="Per substituir","Substituir",IF(OR(N12="No localitzat",N12="No lliurat"),"Reposar",IF(I12<H12,"Reposar",IF(I12>H12,"Revisar excedent",IF(AND(G12="Sí",M12<>"",M12<TODAY()),"EPI caducat",IF(AND(G12="Sí",M12<>"",M12<=TODAY()+90),"EPI caduca ≤90 dies",IF(OR(N12="Deteriorat usable",N12="Revisió necessària"),"Revisar","OK"))))))))))
A13: 1 | B13: =IFERROR(VLOOKUP(A13,Personal!$A$6:$F$112,2,FALSE()),"") -> 0 | C13: =IFERROR(VLOOKUP(A13,Personal!$A$6:$F$112,3,FALSE()),"") -> Olot | D13: Protecció | E13: CAP-MA-04 | F13: Mascareta autofiltrant FFP3 | G13: Sí | H13: =IF(OR(VLOOKUP(A13,Personal!$A$6:$F$112,5,FALSE())<>"Sí",N13="No aplica"),0,'Catàleg GRAE'!D12) -> 1 | P13: =IF(I13="","",I13-H13) | Q13: =IF(B13="","",IF(N13="No aplica","No aplica",IF(I13="","Pendent",IF(N13="Per substituir","Substituir",IF(OR(N13="No localitzat",N13="No lliurat"),"Reposar",IF(I13<H13,"Reposar",IF(I13>H13,"Revisar excedent",IF(AND(G13="Sí",M13<>"",M13<TODAY()),"EPI caducat",IF(AND(G13="Sí",M13<>"",M13<=TODAY()+90),"EPI caduca ≤90 dies",IF(OR(N13="Deteriorat usable",N13="Revisió necessària"),"Revisar","OK"))))))))))
A14: 1 | B14: =IFERROR(VLOOKUP(A14,Personal!$A$6:$F$112,2,FALSE()),"") -> 0 | C14: =IFERROR(VLOOKUP(A14,Personal!$A$6:$F$112,3,FALSE()),"") -> Olot | D14: Esport | E14: COS-DE-02 | F14: Dessuadora d’esport | G14: No | H14: =IF(OR(VLOOKUP(A14,Personal!$A$6:$F$112,5,FALSE())<>"Sí",N14="No aplica"),0,'Catàleg GRAE'!D13) -> 1 | P14: =IF(I14="","",I14-H14) | Q14: =IF(B14="","",IF(N14="No aplica","No aplica",IF(I14="","Pendent",IF(N14="Per substituir","Substituir",IF(OR(N14="No localitzat",N14="No lliurat"),"Reposar",IF(I14<H14,"Reposar",IF(I14>H14,"Revisar excedent",IF(AND(G14="Sí",M14<>"",M14<TODAY()),"EPI caducat",IF(AND(G14="Sí",M14<>"",M14<=TODAY()+90),"EPI caduca ≤90 dies",IF(OR(N14="Deteriorat usable",N14="Revisió necessària"),"Revisar","OK"))))))))))
A15: 1 | B15: =IFERROR(VLOOKUP(A15,Personal!$A$6:$F$112,2,FALSE()),"") -> 0 | C15: =IFERROR(VLOOKUP(A15,Personal!$A$6:$F$112,3,FALSE()),"") -> Olot | D15: Esport | E15: COS-PA-10 | F15: Pantaló llarg d’esport | G15: No | H15: =IF(OR(VLOOKUP(A15,Personal!$A$6:$F$112,5,FALSE())<>"Sí",N15="No aplica"),0,'Catàleg GRAE'!D14) -> 1 | P15: =IF(I15="","",I15-H15) | Q15: =IF(B15="","",IF(N15="No aplica","No aplica",IF(I15="","Pendent",IF(N15="Per substituir","Substituir",IF(OR(N15="No localitzat",N15="No lliurat"),"Reposar",IF(I15<H15,"Reposar",IF(I15>H15,"Revisar excedent",IF(AND(G15="Sí",M15<>"",M15<TODAY()),"EPI caducat",IF(AND(G15="Sí",M15<>"",M15<=TODAY()+90),"EPI caduca ≤90 dies",IF(OR(N15="Deteriorat usable",N15="Revisió necessària"),"Revisar","OK"))))))))))
A16: 1 | B16: =IFERROR(VLOOKUP(A16,Personal!$A$6:$F$112,2,FALSE()),"") -> 0 | C16: =IFERROR(VLOOKUP(A16,Personal!$A$6:$F$112,3,FALSE()),"") -> Olot | D16: Esport | E16: COS-PA-07 | F16: Pantaló curt d’esport | G16: No | H16: =IF(OR(VLOOKUP(A16,Personal!$A$6:$F$112,5,FALSE())<>"Sí",N16="No aplica"),0,'Catàleg GRAE'!D15) -> 1 | P16: =IF(I16="","",I16-H16) | Q16: =IF(B16="","",IF(N16="No aplica","No aplica",IF(I16="","Pendent",IF(N16="Per substituir","Substituir",IF(OR(N16="No localitzat",N16="No lliurat"),"Reposar",IF(I16<H16,"Reposar",IF(I16>H16,"Revisar excedent",IF(AND(G16="Sí",M16<>"",M16<TODAY()),"EPI caducat",IF(AND(G16="Sí",M16<>"",M16<=TODAY()+90),"EPI caduca ≤90 dies",IF(OR(N16="Deteriorat usable",N16="Revisió necessària"),"Revisar","OK"))))))))))
A17: 1 | B17: =IFERROR(VLOOKUP(A17,Personal!$A$6:$F$112,2,FALSE()),"") -> 0 | C17: =IFERROR(VLOOKUP(A17,Personal!$A$6:$F$112,3,FALSE()),"") -> Olot | D17: Esport | E17: COS-SA-02 | F17: Samarreta d’esport | G17: No | H17: =IF(OR(VLOOKUP(A17,Personal!$A$6:$F$112,5,FALSE())<>"Sí",N17="No aplica"),0,'Catàleg GRAE'!D16) -> 1 | P17: =IF(I17="","",I17-H17) | Q17: =IF(B17="","",IF(N17="No aplica","No aplica",IF(I17="","Pendent",IF(N17="Per substituir","Substituir",IF(OR(N17="No localitzat",N17="No lliurat"),"Reposar",IF(I17<H17,"Reposar",IF(I17>H17,"Revisar excedent",IF(AND(G17="Sí",M17<>"",M17<TODAY()),"EPI caducat",IF(AND(G17="Sí",M17<>"",M17<=TODAY()+90),"EPI caduca ≤90 dies",IF(OR(N17="Deteriorat usable",N17="Revisió necessària"),"Revisar","OK"))))))))))
... A114: 1 | B114: =IFERROR(VLOOKUP(A114,Personal!$A$6:$F$112,2,FALSE()),"") -> 0 | C114: =IFERROR(VLOOKUP(A114,Personal!$A$6:$F$112,3,FALSE()),"") -> Olot | D114: Aquàtic | E114: MAT-CO-42 | F114: Banyador corporatiu GRAE | G114: No | H114: =IF(OR(VLOOKUP(A114,Personal!$A$6:$F$112,5,FALSE())<>"Sí",N114="No aplica"),0,'Catàleg GRAE'!D113) -> 1 | P114: =IF(I114="","",I114-H114) | Q114: =IF(B114="","",IF(N114="No aplica","No aplica",IF(I114="","Pendent",IF(N114="Per substituir","Substituir",IF(OR(N114="No localitzat",N114="No lliurat"),"Reposar",IF(I114<H114,"Reposar",IF(I114>H114,"Revisar excedent",IF(AND(G114="Sí",M114<>"",M114<TODAY()),"EPI caducat",IF(AND(G114="Sí",M114<>"",M114<=TODAY()+90),"EPI caduca ≤90 dies",IF(OR(N114="Deteriorat usable",N114="Revisió necessària"),"Revisar","OK"))))))))))
A115: 2 | B115: =IFERROR(VLOOKUP(A115,Personal!$A$6:$F$112,2,FALSE()),"") -> 0 | C115: =IFERROR(VLOOKUP(A115,Personal!$A$6:$F$112,3,FALSE()),"") -> Olot | D115: Uniformitat | E115: COS-PO-02 | F115: Polo màniga curta blau marí (bomber/a) | G115: No | H115: =IF(OR(VLOOKUP(A115,Personal!$A$6:$F$112,5,FALSE())<>"Sí",N115="No aplica"),0,'Catàleg GRAE'!D5) -> 1 | P115: =IF(I115="","",I115-H115) | Q115: =IF(B115="","",IF(N115="No aplica","No aplica",IF(I115="","Pendent",IF(N115="Per substituir","Substituir",IF(OR(N115="No localitzat",N115="No lliurat"),"Reposar",IF(I115<H115,"Reposar",IF(I115>H115,"Revisar excedent",IF(AND(G115="Sí",M115<>"",M115<TODAY()),"EPI caducat",IF(AND(G115="Sí",M115<>"",M115<=TODAY()+90),"EPI caduca ≤90 dies",IF(OR(N115="Deteriorat usable",N115="Revisió necessària"),"Revisar","OK"))))))))))
A116: 2 | B116: =IFERROR(VLOOKUP(A116,Personal!$A$6:$F$112,2,FALSE()),"") -> 0 | C116: =IFERROR(VLOOKUP(A116,Personal!$A$6:$F$112,3,FALSE()),"") -> Olot | D116: Uniformitat | E116: COS-PO-02 | F116: Polo màniga llarga blau marí (bomber/a) | G116: No | H116: =IF(OR(VLOOKUP(A116,Personal!$A$6:$F$112,5,FALSE())<>"Sí",N116="No aplica"),0,'Catàleg GRAE'!D6) -> 1 | P116: =IF(I116="","",I116-H116) | Q116: =IF(B116="","",IF(N116="No aplica","No aplica",IF(I116="","Pendent",IF(N116="Per substituir","Substituir",IF(OR(N116="No localitzat",N116="No lliurat"),"Reposar",IF(I116<H116,"Reposar",IF(I116>H116,"Revisar excedent",IF(AND(G116="Sí",M116<>"",M116<TODAY()),"EPI caducat",IF(AND(G116="Sí",M116<>"",M116<=TODAY()+90),"EPI caduca ≤90 dies",IF(OR(N116="Deteriorat usable",N116="Revisió necessària"),"Revisar","OK"))))))))))
A117: 2 | B117: =IFERROR(VLOOKUP(A117,Personal!$A$6:$F$112,2,FALSE()),"") -> 0 | C117: =IFERROR(VLOOKUP(A117,Personal!$A$6:$F$112,3,FALSE()),"") -> Olot | D117: Uniformitat | E117: COS-PA-08 | F117: Pantaló d’intervenció lleuger | G117: Sí | H117: =IF(OR(VLOOKUP(A117,Personal!$A$6:$F$112,5,FALSE())<>"Sí",N117="No aplica"),0,'Catàleg GRAE'!D7) -> 1 | P117: =IF(I117="","",I117-H117) | Q117: =IF(B117="","",IF(N117="No aplica","No aplica",IF(I117="","Pendent",IF(N117="Per substituir","Substituir",IF(OR(N117="No localitzat",N117="No lliurat"),"Reposar",IF(I117<H117,"Reposar",IF(I117>H117,"Revisar excedent",IF(AND(G117="Sí",M117<>"",M117<TODAY()),"EPI caducat",IF(AND(G117="Sí",M117<>"",M117<=TODAY()+90),"EPI caduca ≤90 dies",IF(OR(N117="Deteriorat usable",N117="Revisió necessària"),"Revisar","OK"))))))))))
A118: 2 | B118: =IFERROR(VLOOKUP(A118,Personal!$A$6:$F$112,2,FALSE()),"") -> 0 | C118: =IFERROR(VLOOKUP(A118,Personal!$A$6:$F$112,3,FALSE()),"") -> Olot | D118: Uniformitat | E118: COS-SA-01 | F118: Samarreta | G118: No | H118: =IF(OR(VLOOKUP(A118,Personal!$A$6:$F$112,5,FALSE())<>"Sí",N118="No aplica"),0,'Catàleg GRAE'!D8) -> 2 | P118: =IF(I118="","",I118-H118) | Q118: =IF(B118="","",IF(N118="No aplica","No aplica",IF(I118="","Pendent",IF(N118="Per substituir","Substituir",IF(OR(N118="No localitzat",N118="No lliurat"),"Reposar",IF(I118<H118,"Reposar",IF(I118>H118,"Revisar excedent",IF(AND(G118="Sí",M118<>"",M118<TODAY()),"EPI caducat",IF(AND(G118="Sí",M118<>"",M118<=TODAY()+90),"EPI caduca ≤90 dies",IF(OR(N118="Deteriorat usable",N118="Revisió necessària"),"Revisar","OK"))))))))))
A119: 2 | B119: =IFERROR(VLOOKUP(A119,Personal!$A$6:$F$112,2,FALSE()),"") -> 0 | C119: =IFERROR(VLOOKUP(A119,Personal!$A$6:$F$112,3,FALSE()),"") -> Olot | D119: Uniformitat | E119: COS-CI-01 | F119: Cinturó de treball | G119: No | H119: =IF(OR(VLOOKUP(A119,Personal!$A$6:$F$112,5,FALSE())<>"Sí",N119="No aplica"),0,'Catàleg GRAE'!D9) -> 1 | P119: =IF(I119="","",I119-H119) | Q119: =IF(B119="","",IF(N119="No aplica","No aplica",IF(I119="","Pendent",IF(N119="Per substituir","Substituir",IF(OR(N119="No localitzat",N119="No lliurat"),"Reposar",IF(I119<H119,"Reposar",IF(I119>H119,"Revisar excedent",IF(AND(G119="Sí",M119<>"",M119<TODAY()),"EPI caducat",IF(AND(G119="Sí",M119<>"",M119<=TODAY()+90),"EPI caduca ≤90 dies",IF(OR(N119="Deteriorat usable",N119="Revisió necessària"),"Revisar","OK"))))))))))
A120: 2 | B120: =IFERROR(VLOOKUP(A120,Personal!$A$6:$F$112,2,FALSE()),"") -> 0 | C120: =IFERROR(VLOOKUP(A120,Personal!$A$6:$F$112,3,FALSE()),"") -> Olot | D120: Transport | E120: MAT-BO-01 / MAT-BO-07 | F120: Bossa de transport amb motxilla | G120: No | H120: =IF(OR(VLOOKUP(A120,Personal!$A$6:$F$112,5,FALSE())<>"Sí",N120="No aplica"),0,'Catàleg GRAE'!D10) -> 1 | P120: =IF(I120="","",I120-H120) | Q120: =IF(B120="","",IF(N120="No aplica","No aplica",IF(I120="","Pendent",IF(N120="Per substituir","Substituir",IF(OR(N120="No localitzat",N120="No lliurat"),"Reposar",IF(I120<H120,"Reposar",IF(I120>H120,"Revisar excedent",IF(AND(G120="Sí",M120<>"",M120<TODAY()),"EPI caducat",IF(AND(G120="Sí",M120<>"",M120<=TODAY()+90),"EPI caduca ≤90 dies",IF(OR(N120="Deteriorat usable",N120="Revisió necessària"),"Revisar","OK"))))))))))
A121: 2 | B121: =IFERROR(VLOOKUP(A121,Personal!$A$6:$F$112,2,FALSE()),"") -> 0 | C121: =IFERROR(VLOOKUP(A121,Personal!$A$6:$F$112,3,FALSE()),"") -> Olot | D121: Protecció | E121: MAN-FO-01 | F121: Guants de protecció en incendis forestals | G121: Sí | H121: =IF(OR(VLOOKUP(A121,Personal!$A$6:$F$112,5,FALSE())<>"Sí",N121="No aplica"),0,'Catàleg GRAE'!D11) -> 1 | P121: =IF(I121="","",I121-H121) | Q121: =IF(B121="","",IF(N121="No aplica","No aplica",IF(I121="","Pendent",IF(N121="Per substituir","Substituir",IF(OR(N121="No localitzat",N121="No lliurat"),"Reposar",IF(I121<H121,"Reposar",IF(I121>H121,"Revisar excedent",IF(AND(G121="Sí",M121<>"",M121<TODAY()),"EPI caducat",IF(AND(G121="Sí",M121<>"",M121<=TODAY()+90),"EPI caduca ≤90 dies",IF(OR(N121="Deteriorat usable",N121="Revisió necessària"),"Revisar","OK"))))))))))
A122: 2 | B122: =IFERROR(VLOOKUP(A122,Personal!$A$6:$F$112,2,FALSE()),"") -> 0 | C122: =IFERROR(VLOOKUP(A122,Personal!$A$6:$F$112,3,FALSE()),"") -> Olot | D122: Protecció | E122: CAP-MA-04 | F122: Mascareta autofiltrant FFP3 | G122: Sí | H122: =IF(OR(VLOOKUP(A122,Personal!$A$6:$F$112,5,FALSE())<>"Sí",N122="No aplica"),0,'Catàleg GRAE'!D12) -> 1 | P122: =IF(I122="","",I122-H122) | Q122: =IF(B122="","",IF(N122="No aplica","No aplica",IF(I122="","Pendent",IF(N122="Per substituir","Substituir",IF(OR(N122="No localitzat",N122="No lliurat"),"Reposar",IF(I122<H122,"Reposar",IF(I122>H122,"Revisar excedent",IF(AND(G122="Sí",M122<>"",M122<TODAY()),"EPI caducat",IF(AND(G122="Sí",M122<>"",M122<=TODAY()+90),"EPI caduca ≤90 dies",IF(OR(N122="Deteriorat usable",N122="Revisió necessària"),"Revisar","OK"))))))))))
A123: 2 | B123: =IFERROR(VLOOKUP(A123,Personal!$A$6:$F$112,2,FALSE()),"") -> 0 | C123: =IFERROR(VLOOKUP(A123,Personal!$A$6:$F$112,3,FALSE()),"") -> Olot | D123: Esport | E123: COS-DE-02 | F123: Dessuadora d’esport | G123: No | H123: =IF(OR(VLOOKUP(A123,Personal!$A$6:$F$112,5,FALSE())<>"Sí",N123="No aplica"),0,'Catàleg GRAE'!D13) -> 1 | P123: =IF(I123="","",I123-H123) | Q123: =IF(B123="","",IF(N123="No aplica","No aplica",IF(I123="","Pendent",IF(N123="Per substituir","Substituir",IF(OR(N123="No localitzat",N123="No lliurat"),"Reposar",IF(I123<H123,"Reposar",IF(I123>H123,"Revisar excedent",IF(AND(G123="Sí",M123<>"",M123<TODAY()),"EPI caducat",IF(AND(G123="Sí",M123<>"",M123<=TODAY()+90),"EPI caduca ≤90 dies",IF(OR(N123="Deteriorat usable",N123="Revisió necessària"),"Revisar","OK"))))))))))
A124: 2 | B124: =IFERROR(VLOOKUP(A124,Personal!$A$6:$F$112,2,FALSE()),"") -> 0 | C124: =IFERROR(VLOOKUP(A124,Personal!$A$6:$F$112,3,FALSE()),"") -> Olot | D124: Esport | E124: COS-PA-10 | F124: Pantaló llarg d’esport | G124: No | H124: =IF(OR(VLOOKUP(A124,Personal!$A$6:$F$112,5,FALSE())<>"Sí",N124="No aplica"),0,'Catàleg GRAE'!D14) -> 1 | P124: =IF(I124="","",I124-H124) | Q124: =IF(B124="","",IF(N124="No aplica","No aplica",IF(I124="","Pendent",IF(N124="Per substituir","Substituir",IF(OR(N124="No localitzat",N124="No lliurat"),"Reposar",IF(I124<H124,"Reposar",IF(I124>H124,"Revisar excedent",IF(AND(G124="Sí",M124<>"",M124<TODAY()),"EPI caducat",IF(AND(G124="Sí",M124<>"",M124<=TODAY()+90),"EPI caduca ≤90 dies",IF(OR(N124="Deteriorat usable",N124="Revisió necessària"),"Revisar","OK"))))))))))
A125: 2 | B125: =IFERROR(VLOOKUP(A125,Personal!$A$6:$F$112,2,FALSE()),"") -> 0 | C125: =IFERROR(VLOOKUP(A125,Personal!$A$6:$F$112,3,FALSE()),"") -> Olot | D125: Esport | E125: COS-PA-07 | F125: Pantaló curt d’esport | G125: No | H125: =IF(OR(VLOOKUP(A125,Personal!$A$6:$F$112,5,FALSE())<>"Sí",N125="No aplica"),0,'Catàleg GRAE'!D15) -> 1 | P125: =IF(I125="","",I125-H125) | Q125: =IF(B125="","",IF(N125="No aplica","No aplica",IF(I125="","Pendent",IF(N125="Per substituir","Substituir",IF(OR(N125="No localitzat",N125="No lliurat"),"Reposar",IF(I125<H125,"Reposar",IF(I125>H125,"Revisar excedent",IF(AND(G125="Sí",M125<>"",M125<TODAY()),"EPI caducat",IF(AND(G125="Sí",M125<>"",M125<=TODAY()+90),"EPI caduca ≤90 dies",IF(OR(N125="Deteriorat usable",N125="Revisió necessària"),"Revisar","OK"))))))))))
A126: 2 | B126: =IFERROR(VLOOKUP(A126,Personal!$A$6:$F$112,2,FALSE()),"") -> 0 | C126: =IFERROR(VLOOKUP(A126,Personal!$A$6:$F$112,3,FALSE()),"") -> Olot | D126: Esport | E126: COS-SA-02 | F126: Samarreta d’esport | G126: No | H126: =IF(OR(VLOOKUP(A126,Personal!$A$6:$F$112,5,FALSE())<>"Sí",N126="No aplica"),0,'Catàleg GRAE'!D16) -> 1 | P126: =IF(I126="","",I126-H126) | Q126: =IF(B126="","",IF(N126="No aplica","No aplica",IF(I126="","Pendent",IF(N126="Per substituir","Substituir",IF(OR(N126="No localitzat",N126="No lliurat"),"Reposar",IF(I126<H126,"Reposar",IF(I126>H126,"Revisar excedent",IF(AND(G126="Sí",M126<>"",M126<TODAY()),"EPI caducat",IF(AND(G126="Sí",M126<>"",M126<=TODAY()+90),"EPI caduca ≤90 dies",IF(OR(N126="Deteriorat usable",N126="Revisió necessària"),"Revisar","OK"))))))))))
... A223: 2 | B223: =IFERROR(VLOOKUP(A223,Personal!$A$6:$F$112,2,FALSE()),"") -> 0 | C223: =IFERROR(VLOOKUP(A223,Personal!$A$6:$F$112,3,FALSE()),"") -> Olot | D223: Aquàtic | E223: MAT-CO-42 | F223: Banyador corporatiu GRAE | G223: No | H223: =IF(OR(VLOOKUP(A223,Personal!$A$6:$F$112,5,FALSE())<>"Sí",N223="No aplica"),0,'Catàleg GRAE'!D113) -> 1 | P223: =IF(I223="","",I223-H223) | Q223: =IF(B223="","",IF(N223="No aplica","No aplica",IF(I223="","Pendent",IF(N223="Per substituir","Substituir",IF(OR(N223="No localitzat",N223="No lliurat"),"Reposar",IF(I223<H223,"Reposar",IF(I223>H223,"Revisar excedent",IF(AND(G223="Sí",M223<>"",M223<TODAY()),"EPI caducat",IF(AND(G223="Sí",M223<>"",M223<=TODAY()+90),"EPI caduca ≤90 dies",IF(OR(N223="Deteriorat usable",N223="Revisió necessària"),"Revisar","OK"))))))))))
A224: 3 | B224: =IFERROR(VLOOKUP(A224,Personal!$A$6:$F$112,2,FALSE()),"") -> 0 | C224: =IFERROR(VLOOKUP(A224,Personal!$A$6:$F$112,3,FALSE()),"") -> Olot | D224: Uniformitat | E224: COS-PO-02 | F224: Polo màniga curta blau marí (bomber/a) | G224: No | H224: =IF(OR(VLOOKUP(A224,Personal!$A$6:$F$112,5,FALSE())<>"Sí",N224="No aplica"),0,'Catàleg GRAE'!D5) -> 1 | P224: =IF(I224="","",I224-H224) | Q224: =IF(B224="","",IF(N224="No aplica","No aplica",IF(I224="","Pendent",IF(N224="Per substituir","Substituir",IF(OR(N224="No localitzat",N224="No lliurat"),"Reposar",IF(I224<H224,"Reposar",IF(I224>H224,"Revisar excedent",IF(AND(G224="Sí",M224<>"",M224<TODAY()),"EPI caducat",IF(AND(G224="Sí",M224<>"",M224<=TODAY()+90),"EPI caduca ≤90 dies",IF(OR(N224="Deteriorat usable",N224="Revisió necessària"),"Revisar","OK"))))))))))
A225: 3 | B225: =IFERROR(VLOOKUP(A225,Personal!$A$6:$F$112,2,FALSE()),"") -> 0 | C225: =IFERROR(VLOOKUP(A225,Personal!$A$6:$F$112,3,FALSE()),"") -> Olot | D225: Uniformitat | E225: COS-PO-02 | F225: Polo màniga llarga blau marí (bomber/a) | G225: No | H225: =IF(OR(VLOOKUP(A225,Personal!$A$6:$F$112,5,FALSE())<>"Sí",N225="No aplica"),0,'Catàleg GRAE'!D6) -> 1 | P225: =IF(I225="","",I225-H225) | Q225: =IF(B225="","",IF(N225="No aplica","No aplica",IF(I225="","Pendent",IF(N225="Per substituir","Substituir",IF(OR(N225="No localitzat",N225="No lliurat"),"Reposar",IF(I225<H225,"Reposar",IF(I225>H225,"Revisar excedent",IF(AND(G225="Sí",M225<>"",M225<TODAY()),"EPI caducat",IF(AND(G225="Sí",M225<>"",M225<=TODAY()+90),"EPI caduca ≤90 dies",IF(OR(N225="Deteriorat usable",N225="Revisió necessària"),"Revisar","OK"))))))))))
A226: 3 | B226: =IFERROR(VLOOKUP(A226,Personal!$A$6:$F$112,2,FALSE()),"") -> 0 | C226: =IFERROR(VLOOKUP(A226,Personal!$A$6:$F$112,3,FALSE()),"") -> Olot | D226: Uniformitat | E226: COS-PA-08 | F226: Pantaló d’intervenció lleuger | G226: Sí | H226: =IF(OR(VLOOKUP(A226,Personal!$A$6:$F$112,5,FALSE())<>"Sí",N226="No aplica"),0,'Catàleg GRAE'!D7) -> 1 | P226: =IF(I226="","",I226-H226) | Q226: =IF(B226="","",IF(N226="No aplica","No aplica",IF(I226="","Pendent",IF(N226="Per substituir","Substituir",IF(OR(N226="No localitzat",N226="No lliurat"),"Reposar",IF(I226<H226,"Reposar",IF(I226>H226,"Revisar excedent",IF(AND(G226="Sí",M226<>"",M226<TODAY()),"EPI caducat",IF(AND(G226="Sí",M226<>"",M226<=TODAY()+90),"EPI caduca ≤90 dies",IF(OR(N226="Deteriorat usable",N226="Revisió necessària"),"Revisar","OK"))))))))))
A227: 3 | B227: =IFERROR(VLOOKUP(A227,Personal!$A$6:$F$112,2,FALSE()),"") -> 0 | C227: =IFERROR(VLOOKUP(A227,Personal!$A$6:$F$112,3,FALSE()),"") -> Olot | D227: Uniformitat | E227: COS-SA-01 | F227: Samarreta | G227: No | H227: =IF(OR(VLOOKUP(A227,Personal!$A$6:$F$112,5,FALSE())<>"Sí",N227="No aplica"),0,'Catàleg GRAE'!D8) -> 2 | P227: =IF(I227="","",I227-H227) | Q227: =IF(B227="","",IF(N227="No aplica","No aplica",IF(I227="","Pendent",IF(N227="Per substituir","Substituir",IF(OR(N227="No localitzat",N227="No lliurat"),"Reposar",IF(I227<H227,"Reposar",IF(I227>H227,"Revisar excedent",IF(AND(G227="Sí",M227<>"",M227<TODAY()),"EPI caducat",IF(AND(G227="Sí",M227<>"",M227<=TODAY()+90),"EPI caduca ≤90 dies",IF(OR(N227="Deteriorat usable",N227="Revisió necessària"),"Revisar","OK"))))))))))
A228: 3 | B228: =IFERROR(VLOOKUP(A228,Personal!$A$6:$F$112,2,FALSE()),"") -> 0 | C228: =IFERROR(VLOOKUP(A228,Personal!$A$6:$F$112,3,FALSE()),"") -> Olot | D228: Uniformitat | E228: COS-CI-01 | F228: Cinturó de treball | G228: No | H228: =IF(OR(VLOOKUP(A228,Personal!$A$6:$F$112,5,FALSE())<>"Sí",N228="No aplica"),0,'Catàleg GRAE'!D9) -> 1 | P228: =IF(I228="","",I228-H228) | Q228: =IF(B228="","",IF(N228="No aplica","No aplica",IF(I228="","Pendent",IF(N228="Per substituir","Substituir",IF(OR(N228="No localitzat",N228="No lliurat"),"Reposar",IF(I228<H228,"Reposar",IF(I228>H228,"Revisar excedent",IF(AND(G228="Sí",M228<>"",M228<TODAY()),"EPI caducat",IF(AND(G228="Sí",M228<>"",M228<=TODAY()+90),"EPI caduca ≤90 dies",IF(OR(N228="Deteriorat usable",N228="Revisió necessària"),"Revisar","OK"))))))))))
A229: 3 | B229: =IFERROR(VLOOKUP(A229,Personal!$A$6:$F$112,2,FALSE()),"") -> 0 | C229: =IFERROR(VLOOKUP(A229,Personal!$A$6:$F$112,3,FALSE()),"") -> Olot | D229: Transport | E229: MAT-BO-01 / MAT-BO-07 | F229: Bossa de transport amb motxilla | G229: No | H229: =IF(OR(VLOOKUP(A229,Personal!$A$6:$F$112,5,FALSE())<>"Sí",N229="No aplica"),0,'Catàleg GRAE'!D10) -> 1 | P229: =IF(I229="","",I229-H229) | Q229: =IF(B229="","",IF(N229="No aplica","No aplica",IF(I229="","Pendent",IF(N229="Per substituir","Substituir",IF(OR(N229="No localitzat",N229="No lliurat"),"Reposar",IF(I229<H229,"Reposar",IF(I229>H229,"Revisar excedent",IF(AND(G229="Sí",M229<>"",M229<TODAY()),"EPI caducat",IF(AND(G229="Sí",M229<>"",M229<=TODAY()+90),"EPI caduca ≤90 dies",IF(OR(N229="Deteriorat usable",N229="Revisió necessària"),"Revisar","OK"))))))))))
A230: 3 | B230: =IFERROR(VLOOKUP(A230,Personal!$A$6:$F$112,2,FALSE()),"") -> 0 | C230: =IFERROR(VLOOKUP(A230,Personal!$A$6:$F$112,3,FALSE()),"") -> Olot | D230: Protecció | E230: MAN-FO-01 | F230: Guants de protecció en incendis forestals | G230: Sí | H230: =IF(OR(VLOOKUP(A230,Personal!$A$6:$F$112,5,FALSE())<>"Sí",N230="No aplica"),0,'Catàleg GRAE'!D11) -> 1 | P230: =IF(I230="","",I230-H230) | Q230: =IF(B230="","",IF(N230="No aplica","No aplica",IF(I230="","Pendent",IF(N230="Per substituir","Substituir",IF(OR(N230="No localitzat",N230="No lliurat"),"Reposar",IF(I230<H230,"Reposar",IF(I230>H230,"Revisar excedent",IF(AND(G230="Sí",M230<>"",M230<TODAY()),"EPI caducat",IF(AND(G230="Sí",M230<>"",M230<=TODAY()+90),"EPI caduca ≤90 dies",IF(OR(N230="Deteriorat usable",N230="Revisió necessària"),"Revisar","OK"))))))))))
A231: 3 | B231: =IFERROR(VLOOKUP(A231,Personal!$A$6:$F$112,2,FALSE()),"") -> 0 | C231: =IFERROR(VLOOKUP(A231,Personal!$A$6:$F$112,3,FALSE()),"") -> Olot | D231: Protecció | E231: CAP-MA-04 | F231: Mascareta autofiltrant FFP3 | G231: Sí | H231: =IF(OR(VLOOKUP(A231,Personal!$A$6:$F$112,5,FALSE())<>"Sí",N231="No aplica"),0,'Catàleg GRAE'!D12) -> 1 | P231: =IF(I231="","",I231-H231) | Q231: =IF(B231="","",IF(N231="No aplica","No aplica",IF(I231="","Pendent",IF(N231="Per substituir","Substituir",IF(OR(N231="No localitzat",N231="No lliurat"),"Reposar",IF(I231<H231,"Reposar",IF(I231>H231,"Revisar excedent",IF(AND(G231="Sí",M231<>"",M231<TODAY()),"EPI caducat",IF(AND(G231="Sí",M231<>"",M231<=TODAY()+90),"EPI caduca ≤90 dies",IF(OR(N231="Deteriorat usable",N231="Revisió necessària"),"Revisar","OK"))))))))))
A232: 3 | B232: =IFERROR(VLOOKUP(A232,Personal!$A$6:$F$112,2,FALSE()),"") -> 0 | C232: =IFERROR(VLOOKUP(A232,Personal!$A$6:$F$112,3,FALSE()),"") -> Olot | D232: Esport | E232: COS-DE-02 | F232: Dessuadora d’esport | G232: No | H232: =IF(OR(VLOOKUP(A232,Personal!$A$6:$F$112,5,FALSE())<>"Sí",N232="No aplica"),0,'Catàleg GRAE'!D13) -> 1 | P232: =IF(I232="","",I232-H232) | Q232: =IF(B232="","",IF(N232="No aplica","No aplica",IF(I232="","Pendent",IF(N232="Per substituir","Substituir",IF(OR(N232="No localitzat",N232="No lliurat"),"Reposar",IF(I232<H232,"Reposar",IF(I232>H232,"Revisar excedent",IF(AND(G232="Sí",M232<>"",M232<TODAY()),"EPI caducat",IF(AND(G232="Sí",M232<>"",M232<=TODAY()+90),"EPI caduca ≤90 dies",IF(OR(N232="Deteriorat usable",N232="Revisió necessària"),"Revisar","OK"))))))))))
A233: 3 | B233: =IFERROR(VLOOKUP(A233,Personal!$A$6:$F$112,2,FALSE()),"") -> 0 | C233: =IFERROR(VLOOKUP(A233,Personal!$A$6:$F$112,3,FALSE()),"") -> Olot | D233: Esport | E233: COS-PA-10 | F233: Pantaló llarg d’esport | G233: No | H233: =IF(OR(VLOOKUP(A233,Personal!$A$6:$F$112,5,FALSE())<>"Sí",N233="No aplica"),0,'Catàleg GRAE'!D14) -> 1 | P233: =IF(I233="","",I233-H233) | Q233: =IF(B233="","",IF(N233="No aplica","No aplica",IF(I233="","Pendent",IF(N233="Per substituir","Substituir",IF(OR(N233="No localitzat",N233="No lliurat"),"Reposar",IF(I233<H233,"Reposar",IF(I233>H233,"Revisar excedent",IF(AND(G233="Sí",M233<>"",M233<TODAY()),"EPI caducat",IF(AND(G233="Sí",M233<>"",M233<=TODAY()+90),"EPI caduca ≤90 dies",IF(OR(N233="Deteriorat usable",N233="Revisió necessària"),"Revisar","OK"))))))))))
A234: 3 | B234: =IFERROR(VLOOKUP(A234,Personal!$A$6:$F$112,2,FALSE()),"") -> 0 | C234: =IFERROR(VLOOKUP(A234,Personal!$A$6:$F$112,3,FALSE()),"") -> Olot | D234: Esport | E234: COS-PA-07 | F234: Pantaló curt d’esport | G234: No | H234: =IF(OR(VLOOKUP(A234,Personal!$A$6:$F$112,5,FALSE())<>"Sí",N234="No aplica"),0,'Catàleg GRAE'!D15) -> 1 | P234: =IF(I234="","",I234-H234) | Q234: =IF(B234="","",IF(N234="No aplica","No aplica",IF(I234="","Pendent",IF(N234="Per substituir","Substituir",IF(OR(N234="No localitzat",N234="No lliurat"),"Reposar",IF(I234<H234,"Reposar",IF(I234>H234,"Revisar excedent",IF(AND(G234="Sí",M234<>"",M234<TODAY()),"EPI caducat",IF(AND(G234="Sí",M234<>"",M234<=TODAY()+90),"EPI caduca ≤90 dies",IF(OR(N234="Deteriorat usable",N234="Revisió necessària"),"Revisar","OK"))))))))))
...

Sheet Catàleg GRAE
A2: Catàleg de dotació individual - GRAE Muntanya
A4: Categoria | B4: Referència | C4: Article | D4: Dotació teòrica / persona | E4: EPI traçable
A5: Uniformitat | B5: COS-PO-02 | C5: Polo màniga curta blau marí (bomber/a) | D5: 1 | E5: No
A6: Uniformitat | B6: COS-PO-02 | C6: Polo màniga llarga blau marí (bomber/a) | D6: 1 | E6: No
A7: Uniformitat | B7: COS-PA-08 | C7: Pantaló d’intervenció lleuger | D7: 1 | E7: Sí
A8: Uniformitat | B8: COS-SA-01 | C8: Samarreta | D8: 2 | E8: No
A9: Uniformitat | B9: COS-CI-01 | C9: Cinturó de treball | D9: 1 | E9: No
A10: Transport | B10: MAT-BO-01 / MAT-BO-07 | C10: Bossa de transport amb motxilla | D10: 1 | E10: No
A11: Protecció | B11: MAN-FO-01 | C11: Guants de protecció en incendis forestals | D11: 1 | E11: Sí
A12: Protecció | B12: CAP-MA-04 | C12: Mascareta autofiltrant FFP3 | D12: 1 | E12: Sí
A13: Esport | B13: COS-DE-02 | C13: Dessuadora d’esport | D13: 1 | E13: No
A14: Esport | B14: COS-PA-10 | C14: Pantaló llarg d’esport | D14: 1 | E14: No
A15: Esport | B15: COS-PA-07 | C15: Pantaló curt d’esport | D15: 1 | E15: No
A16: Esport | B16: COS-SA-02 | C16: Samarreta d’esport | D16: 1 | E16: No
... A113: Aquàtic | B113: MAT-CO-42 | C113: Banyador corporatiu GRAE | D113: 1 | E113: No

Sheet Guia acció
A2: Guia per executar l’acció d’inventari
A5: Objectiu | B5: Disposar d’un inventari nominal, verificat i comparable amb la dotació DOC.STT.001 V.2 2026.
A6: Abast | B6: Tot el personal especialista GRAE Muntanya i tota la dotació individual de l’apartat 1.2 del catàleg.
A7: 1. Preparació | B7: Completar la pestanya Personal, assignar una persona responsable per base i fixar una data límit comuna.
A8: 2. Autoinventari | B8: Cada especialista filtra la pestanya Declaracions pel seu ID i informa unitats, talla, estat, revisió i observacions.
A9: 3. Verificació | B9: Fer comprovació física per parelles o per un responsable de base. Marcar Comprovat = Sí.
A10: 4. Consolidació | B10: Revisar la pestanya Resum i filtrar Situació = Reposar o Revisar.
A11: 5. Tancament | B11: Validar incidències, acordar reposicions i conservar una còpia amb la data de tancament.
A12: Criteri - Correcte | B12: Material localitzat, funcional i sense defectes que comprometin l’ús.
A13: Criteri - Deteriorat usable | B13: Té desgast, però es pot continuar utilitzant amb seguretat; cal seguiment.
A14: Criteri - Revisió necessària | B14: Requereix inspecció tècnica, manteniment o comprovació documental.
A15: Criteri - Per substituir | B15: No és apte per al servei o ha arribat al final de vida útil.
A16: Criteri - No localitzat | B16: Consta com a dotació, però no es troba físicament.
... A22: Nota | B22: Les referències compartides per peces de màniga curta/llarga i les que depenen de categoria s’han mantingut agrupades segons el catàleg.
